[2025-04-04T16:36:30.567+0000] {local_task_job_runner.py:123} INFO - ::group::Pre task execution logs
[2025-04-04T16:36:30.579+0000] {taskinstance.py:2614} INFO - Dependencies all met for dep_context=non-requeueable deps ti=<TaskInstance: check_queries.test3.txt manual__2025-04-04T16:32:30.998216+00:00 [queued]>
[2025-04-04T16:36:30.590+0000] {taskinstance.py:2614} INFO - Dependencies all met for dep_context=requeueable deps ti=<TaskInstance: check_queries.test3.txt manual__2025-04-04T16:32:30.998216+00:00 [queued]>
[2025-04-04T16:36:30.591+0000] {taskinstance.py:2867} INFO - Starting attempt 1 of 1
[2025-04-04T16:36:30.616+0000] {taskinstance.py:2890} INFO - Executing <Task(_PythonDecoratedOperator): test3.txt> on 2025-04-04 16:32:30.998216+00:00
[2025-04-04T16:36:30.625+0000] {standard_task_runner.py:72} INFO - Started process 1964085 to run task
[2025-04-04T16:36:30.630+0000] {standard_task_runner.py:104} INFO - Running: ['airflow', 'tasks', 'run', 'check_queries', 'test3.txt', 'manual__2025-04-04T16:32:30.998216+00:00', '--job-id', '132', '--raw', '--subdir', 'DAGS_FOLDER/check_queries_prototype.py', '--cfg-path', '/tmp/tmp2nybxw4t']
[2025-04-04T16:36:30.634+0000] {standard_task_runner.py:105} INFO - Job 132: Subtask test3.txt
[2025-04-04T16:36:30.829+0000] {task_command.py:467} INFO - Running <TaskInstance: check_queries.test3.txt manual__2025-04-04T16:32:30.998216+00:00 [running]> on host ubuntu-s-2vcpu-4gb-amd-sfo3-01
[2025-04-04T16:36:32.563+0000] {taskinstance.py:3134} INFO - Exporting env vars: AIRFLOW_CTX_DAG_OWNER='airflow' AIRFLOW_CTX_DAG_ID='check_queries' AIRFLOW_CTX_TASK_ID='test3.txt' AIRFLOW_CTX_EXECUTION_DATE='2025-04-04T16:32:30.998216+00:00' AIRFLOW_CTX_TRY_NUMBER='1' AIRFLOW_CTX_DAG_RUN_ID='manual__2025-04-04T16:32:30.998216+00:00'
[2025-04-04T16:36:32.597+0000] {taskinstance.py:732} INFO - ::endgroup::
[2025-04-04T16:38:36.520+0000] {connectionpool.py:868} WARNING - Retrying (Retry(total=2, connect=None, read=None, redirect=None, status=None)) after connection broken by 'SSLEOFError(8, 'EOF occurred in violation of protocol (_ssl.c:2417)')': /token
[2025-04-04T16:38:37.016+0000] {job.py:229} INFO - Heartbeat recovered after 126.50 seconds
[2025-04-04T16:38:43.005+0000] {python.py:240} INFO - Done. Returned value was: success
[2025-04-04T16:38:57.904+0000] {taskinstance.py:341} INFO - ::group::Post task execution logs
[2025-04-04T16:38:57.912+0000] {taskinstance.py:353} INFO - Marking task as SUCCESS. dag_id=check_queries, task_id=test3.txt, run_id=manual__2025-04-04T16:32:30.998216+00:00, execution_date=20250404T163230, start_date=20250404T163630, end_date=20250404T163857
