[2025-04-08T19:54:20.863+0000] {processor.py:186} INFO - Started process (PID=2020176) to work on /root/airflow/dags/check_queries_prototype.py
[2025-04-08T19:54:20.866+0000] {processor.py:914} INFO - Processing file /root/airflow/dags/check_queries_prototype.py for tasks to queue
[2025-04-08T19:54:20.875+0000] {logging_mixin.py:190} INFO - [2025-04-08T19:54:20.869+0000] {dagbag.py:588} INFO - Filling up the DagBag from /root/airflow/dags/check_queries_prototype.py
[2025-04-08T19:54:21.457+0000] {logging_mixin.py:190} INFO - [2025-04-08T19:54:21.446+0000] {dagbag.py:484} ERROR - Failed to bag_dag: /root/airflow/dags/check_queries_prototype.py
Traceback (most recent call last):
  File "/root/venv/lib/python3.12/site-packages/airflow/timetables/_cron.py", line 102, in validate
    croniter(self._expression)
  File "/root/venv/lib/python3.12/site-packages/croniter/croniter.py", line 268, in __init__
    self.expanded, self.nth_weekday_of_month = self.expand(
                                               ^^^^^^^^^^^^
  File "/root/venv/lib/python3.12/site-packages/croniter/croniter.py", line 1113, in expand
    return cls._expand(
           ^^^^^^^^^^^^
  File "/root/venv/lib/python3.12/site-packages/croniter/croniter.py", line 1029, in _expand
    raise CroniterBadCronError("[{0}] is not acceptable, out of range".format(expr_format))
croniter.croniter.CroniterBadCronError: [0 0 0 * *] is not acceptable, out of range

During handling of the above exception, another exception occurred:

Traceback (most recent call last):
  File "/root/venv/lib/python3.12/site-packages/airflow/models/dagbag.py", line 479, in _process_modules
    dag.validate()
  File "/root/venv/lib/python3.12/site-packages/airflow/models/dag.py", line 845, in validate
    self.timetable.validate()
  File "/root/venv/lib/python3.12/site-packages/airflow/timetables/_cron.py", line 104, in validate
    raise AirflowTimetableInvalid(str(e))
airflow.exceptions.AirflowTimetableInvalid: [0 0 0 * *] is not acceptable, out of range
[2025-04-08T19:54:21.458+0000] {processor.py:927} WARNING - No viable dags retrieved from /root/airflow/dags/check_queries_prototype.py
[2025-04-08T19:54:21.563+0000] {processor.py:208} INFO - Processing /root/airflow/dags/check_queries_prototype.py took 0.974 seconds
[2025-04-08T19:54:52.300+0000] {processor.py:186} INFO - Started process (PID=2020188) to work on /root/airflow/dags/check_queries_prototype.py
[2025-04-08T19:54:52.302+0000] {processor.py:914} INFO - Processing file /root/airflow/dags/check_queries_prototype.py for tasks to queue
[2025-04-08T19:54:52.305+0000] {logging_mixin.py:190} INFO - [2025-04-08T19:54:52.305+0000] {dagbag.py:588} INFO - Filling up the DagBag from /root/airflow/dags/check_queries_prototype.py
[2025-04-08T19:54:52.817+0000] {logging_mixin.py:190} INFO - [2025-04-08T19:54:52.806+0000] {dagbag.py:484} ERROR - Failed to bag_dag: /root/airflow/dags/check_queries_prototype.py
Traceback (most recent call last):
  File "/root/venv/lib/python3.12/site-packages/airflow/timetables/_cron.py", line 102, in validate
    croniter(self._expression)
  File "/root/venv/lib/python3.12/site-packages/croniter/croniter.py", line 268, in __init__
    self.expanded, self.nth_weekday_of_month = self.expand(
                                               ^^^^^^^^^^^^
  File "/root/venv/lib/python3.12/site-packages/croniter/croniter.py", line 1113, in expand
    return cls._expand(
           ^^^^^^^^^^^^
  File "/root/venv/lib/python3.12/site-packages/croniter/croniter.py", line 1029, in _expand
    raise CroniterBadCronError("[{0}] is not acceptable, out of range".format(expr_format))
croniter.croniter.CroniterBadCronError: [0 0 0 * *] is not acceptable, out of range

During handling of the above exception, another exception occurred:

Traceback (most recent call last):
  File "/root/venv/lib/python3.12/site-packages/airflow/models/dagbag.py", line 479, in _process_modules
    dag.validate()
  File "/root/venv/lib/python3.12/site-packages/airflow/models/dag.py", line 845, in validate
    self.timetable.validate()
  File "/root/venv/lib/python3.12/site-packages/airflow/timetables/_cron.py", line 104, in validate
    raise AirflowTimetableInvalid(str(e))
airflow.exceptions.AirflowTimetableInvalid: [0 0 0 * *] is not acceptable, out of range
[2025-04-08T19:54:52.818+0000] {processor.py:927} WARNING - No viable dags retrieved from /root/airflow/dags/check_queries_prototype.py
[2025-04-08T19:54:52.846+0000] {processor.py:208} INFO - Processing /root/airflow/dags/check_queries_prototype.py took 0.553 seconds
[2025-04-08T19:55:23.098+0000] {processor.py:186} INFO - Started process (PID=2020197) to work on /root/airflow/dags/check_queries_prototype.py
[2025-04-08T19:55:23.099+0000] {processor.py:914} INFO - Processing file /root/airflow/dags/check_queries_prototype.py for tasks to queue
[2025-04-08T19:55:23.100+0000] {logging_mixin.py:190} INFO - [2025-04-08T19:55:23.099+0000] {dagbag.py:588} INFO - Filling up the DagBag from /root/airflow/dags/check_queries_prototype.py
[2025-04-08T19:55:23.538+0000] {logging_mixin.py:190} INFO - [2025-04-08T19:55:23.529+0000] {dagbag.py:484} ERROR - Failed to bag_dag: /root/airflow/dags/check_queries_prototype.py
Traceback (most recent call last):
  File "/root/venv/lib/python3.12/site-packages/airflow/timetables/_cron.py", line 102, in validate
    croniter(self._expression)
  File "/root/venv/lib/python3.12/site-packages/croniter/croniter.py", line 268, in __init__
    self.expanded, self.nth_weekday_of_month = self.expand(
                                               ^^^^^^^^^^^^
  File "/root/venv/lib/python3.12/site-packages/croniter/croniter.py", line 1113, in expand
    return cls._expand(
           ^^^^^^^^^^^^
  File "/root/venv/lib/python3.12/site-packages/croniter/croniter.py", line 1029, in _expand
    raise CroniterBadCronError("[{0}] is not acceptable, out of range".format(expr_format))
croniter.croniter.CroniterBadCronError: [0 0 0 * *] is not acceptable, out of range

During handling of the above exception, another exception occurred:

Traceback (most recent call last):
  File "/root/venv/lib/python3.12/site-packages/airflow/models/dagbag.py", line 479, in _process_modules
    dag.validate()
  File "/root/venv/lib/python3.12/site-packages/airflow/models/dag.py", line 845, in validate
    self.timetable.validate()
  File "/root/venv/lib/python3.12/site-packages/airflow/timetables/_cron.py", line 104, in validate
    raise AirflowTimetableInvalid(str(e))
airflow.exceptions.AirflowTimetableInvalid: [0 0 0 * *] is not acceptable, out of range
[2025-04-08T19:55:23.538+0000] {processor.py:927} WARNING - No viable dags retrieved from /root/airflow/dags/check_queries_prototype.py
[2025-04-08T19:55:23.560+0000] {processor.py:208} INFO - Processing /root/airflow/dags/check_queries_prototype.py took 0.468 seconds
